Loading cuda/11.3
  Loading requirement: cudnn/8.2.1-cu11.3
Traceback (most recent call last):
  File "/home/raecker1/nako_ukb_age/experiments/gradcam_volume_ukb.py", line 10, in <module>
    import pandas as pd
  File "/opt/conda/rakuest1/envs/nakoukb/lib/python3.8/site-packages/pandas/__init__.py", line 16, in <module>
    raise ImportError(
ImportError: Unable to import required dependencies:
dateutil: No module named 'dateutil'
Traceback (most recent call last):
  File "/home/raecker1/nako_ukb_age/experiments/gradcam_volume_ukb.py", line 10, in <module>
    import pandas as pd
  File "/opt/conda/rakuest1/envs/nakoukb/lib/python3.8/site-packages/pandas/__init__.py", line 16, in <module>
    raise ImportError(
ImportError: Unable to import required dependencies:
dateutil: No module named 'dateutil'
Traceback (most recent call last):
  File "/home/raecker1/nako_ukb_age/experiments/gradcam_volume_ukb.py", line 10, in <module>
    import pandas as pd
  File "/opt/conda/rakuest1/envs/nakoukb/lib/python3.8/site-packages/pandas/__init__.py", line 16, in <module>
    raise ImportError(
ImportError: Unable to import required dependencies:
dateutil: No module named 'dateutil'
Traceback (most recent call last):
  File "/home/raecker1/nako_ukb_age/experiments/gradcam_volume_ukb.py", line 10, in <module>
    import pandas as pd
  File "/opt/conda/rakuest1/envs/nakoukb/lib/python3.8/site-packages/pandas/__init__.py", line 16, in <module>
    raise ImportError(
ImportError: Unable to import required dependencies:
dateutil: No module named 'dateutil'
Traceback (most recent call last):
  File "/home/raecker1/nako_ukb_age/experiments/gradcam_volume_ukb.py", line 10, in <module>
    import pandas as pd
  File "/opt/conda/rakuest1/envs/nakoukb/lib/python3.8/site-packages/pandas/__init__.py", line 16, in <module>
    raise ImportError(
ImportError: Unable to import required dependencies:
dateutil: No module named 'dateutil'
